<?xml version="1.0" encoding="utf-8"?>
<!-- This URDF was automatically created by SolidWorks to URDF Exporter! Originally created by Stephen Brawner (brawner@gmail.com) 
     Commit Version: 1.5.1-0-g916b5db  Build Version: 1.5.7152.31018
     For more information, please see http://wiki.ros.org/sw_urdf_exporter -->
<robot
  name="avatar_r0_5">
  <link
    name="base_link">
    <inertial>
      <origin
        xyz="-0.00059717 0.23425 0.23101"
        rpy="0 0 0" />
      <mass
        value="18.166" />
      <inertia
        ixx="0.27355"
        ixy="-3.5553E-08"
        ixz="1.7118E-08"
        iyy="0.032156"
        iyz="0.026709"
        izz="0.25168" />
    </inertial>
    <visual>
      <origin
        xyz="0 0 0"
        rpy="0 0 0" />
      <geometry>
        <mesh
          filename="meshes/base_link.obj" />
      </geometry>
      <material
        name="">
        <color
          rgba="0.078431 0.078431 0.078431 1" />
      </material>
    </visual>
    <collision>
      <origin
        xyz="0 0 0"
        rpy="0 0 0" />
      <geometry>
        <!-- <mesh
          filename="/meshes/base_link.obj" /> -->
          <mesh
          filename="meshes/base_link.obj" />
      </geometry>
    </collision>
  </link>
  <link
    name="platform_link">
    <inertial>
      <origin
        xyz="-0.0019169 -0.019253 0.12225"
        rpy="0 0 0" />
      <mass
        value="5.2089" />
      <inertia
        ixx="0.097524"
        ixy="-0.0012534"
        ixz="0.0012359"
        iyy="0.12991"
        iyz="0.009425"
        izz="0.12902" />
    </inertial>
    <visual>
      <origin
        xyz="0 0 0"
        rpy="0 0 0" />
      <geometry>
        <mesh
          filename="/meshes/platform_link.obj" />
      </geometry>
      <material
        name="">
        <color
          rgba="0.96078 0.96078 0.96471 1" />
      </material>
    </visual>
    <collision>
      <origin
        xyz="0 0 0"
        rpy="0 0 0" />
      <geometry>
        <mesh
          filename="/meshes/platform_link.obj" />
      </geometry>
    </collision>
  </link>
  <joint
    name="base2platform"
    type="fixed">
    <origin
      xyz="-0.00064398 0.26937 0.44804"
      rpy="0 0 0" />
    <parent
      link="base_link" />
    <child
      link="platform_link" />
    <axis
      xyz="0 0 0" />
  </joint>
  <link
    name="waist_link">
    <inertial>
      <origin
        xyz="0.0018725 -0.0033609 0.1446"
        rpy="0 0 0" />
      <mass
        value="21.191" />
      <inertia
        ixx="0.19935"
        ixy="-1.3224E-06"
        ixz="0.00099714"
        iyy="0.2049"
        iyz="-0.00020488"
        izz="0.21829" />
    </inertial>
    <visual>
      <origin
        xyz="0 0 0"
        rpy="0 0 0" />
      <geometry>
        <mesh
          filename="/meshes/waist_link.obj" />
      </geometry>
      <material
        name="">
        <color
          rgba="0.79216 0.81961 0.93333 1" />
      </material>
    </visual>
    <collision>
      <origin
        xyz="0 0 0"
        rpy="0 0 0" />
      <geometry>
        <mesh
          filename="/meshes/waist_link.obj" />
      </geometry>
    </collision>
  </link>
  <!--joint
    name="waist_rot"
    type="revolute" -->
  <joint
    name="waist_rot"
    type="fixed">
    <origin
      xyz="0 -0.24 -1.325E-05"
      rpy="0 0 -1.5708" />
    <parent
      link="platform_link" />
    <child
      link="waist_link" />
    <axis
      xyz="0 0 -1" />
    <limit
      lower="-1"
      upper="1"
      effort="0"
      velocity="2" />
  </joint>
  <link
    name="chest_link">
    <inertial>
      <origin
        xyz="0.0372440537545067 0.11132546173049 0.0211577100485159"
        rpy="0 0 0" />
      <mass
        value="0.304842527068954" />
      <inertia
        ixx="0.000294481419363187"
        ixy="0.000242567817341944"
        ixz="-5.52363714472291E-07"
        iyy="0.00103928704482828"
        iyz="4.86582984793202E-06"
        izz="0.00120731891145862" />
    </inertial>
    <visual>
      <origin
        xyz="0 0 0"
        rpy="0 0 0" />
      <geometry>
        <mesh
          filename="/meshes/chest_link.obj" />
      </geometry>
      <material
        name="">
        <color
          rgba="0.956862745098039 0.96078431372549 0.964705882352941 1" />
      </material>
    </visual>
    <collision>
      <origin
        xyz="0 0 0"
        rpy="0 0 0" />
      <geometry>
        <mesh
          filename="/meshes/chest_link.obj" />
      </geometry>
    </collision>
  </link>
  <!--joint
    name="waist_tilt"
    type="revolute" -->
  <joint
    name="waist_tilt"
    type="fixed">
    <origin
      xyz="0.026019 0 0.336"
      rpy="1.5708 0 1.5708" />
    <parent
      link="waist_link" />
    <child
      link="chest_link" />
    <axis
      xyz="-1 0 0" />
    <limit
      lower="0"
      upper="1"
      effort="0"
      velocity="2" />
  </joint>
  <link
    name="r_should_axis_link">
    <inertial>
      <origin
        xyz="0.0271747977618289 -2.87714544225082E-05 0.0136872715581331"
        rpy="0 0 0" />
      <mass
        value="0.0760510742436307" />
      <inertia
        ixx="5.01097287434105E-05"
        ixy="3.09946970417366E-08"
        ixz="2.474321199555E-05"
        iyy="0.000103376219183421"
        iyz="1.77481964668466E-08"
        izz="0.000115998977330436" />
    </inertial>
    <visual>
      <origin
        xyz="0 0 0"
        rpy="0 0 0" />
      <geometry>
        <mesh
          filename="/meshes/r_should_axis_link.obj" />
      </geometry>
      <material
        name="">
        <color
          rgba="0.96078431372549 0.96078431372549 0.964705882352941 1" />
      </material>
    </visual>
    <collision>
      <origin
        xyz="0 0 0"
        rpy="0 0 0" />
      <geometry>
        <mesh
          filename="/meshes/r_should_axis_link.obj" />
      </geometry>
    </collision>
  </link>
  <joint
    name="r_should_rot"
    type="revolute">
    <origin
      xyz="-0.10061 0.416 0"
      rpy="1.5708 0 3.1416" />
    <parent
      link="chest_link" />
    <child
      link="r_should_axis_link" />
    <axis
      xyz="0 0 -1" />
    <limit
      lower="-1"
      upper="1"
      effort="0"
      velocity="2" />
  </joint>
  <link
    name="r_interface_link">
  </link>
  <joint
    name="r_rot2int"
    type="fixed">
    <origin
      xyz="0.065 0 0"
      rpy="0 -1.5708 0" />
    <parent
      link="r_should_axis_link" />
    <child
      link="r_interface_link" />
    <axis
      xyz="0 0 0" />
  </joint>
  <link
    name="l_should_axis_link">
    <inertial>
      <origin
        xyz="0.0271746660088268 -7.81820416141978E-05 0.0136872746188932"
        rpy="0 0 0" />
      <mass
        value="0.0760509825087617" />
      <inertia
        ixx="5.01100039793683E-05"
        ixy="1.27864503626856E-07"
        ixz="2.47431993244341E-05"
        iyy="0.000103375868748006"
        iyz="-2.72311343991148E-08"
        izz="0.000115998907803854" />
    </inertial>
    <visual>
      <origin
        xyz="0 0 0"
        rpy="0 0 0" />
      <geometry>
        <mesh
          filename="/meshes/l_should_axis_link.obj" />
      </geometry>
      <material
        name="">
        <color
          rgba="0.96078431372549 0.96078431372549 0.964705882352941 1" />
      </material>
    </visual>
    <collision>
      <origin
        xyz="0 0 0"
        rpy="0 0 0" />
      <geometry>
        <mesh
          filename="/meshes/l_should_axis_link.obj" />
      </geometry>
    </collision>
  </link>
  <joint
    name="l_should_rot"
    type="revolute">
    <origin
      xyz="0.10061 0.416 0"
      rpy="-1.5708 0 0" />
    <parent
      link="chest_link" />
    <child
      link="l_should_axis_link" />
    <axis
      xyz="0 0 -1" />
    <limit
      lower="-1"
      upper="1"
      effort="0"
      velocity="2" />
  </joint>
  <link
    name="l_interface_link">
  </link>
  <joint
    name="l_rot2int"
    type="fixed">
    <origin
      xyz="0.065 0 0"
      rpy="0 -1.5708 0" />
    <parent
      link="l_should_axis_link" />
    <child
      link="l_interface_link" />
    <axis
      xyz="0 0 0" />
  </joint>
  <link
    name="neck_link">
    <inertial>
      <origin
        xyz="0.00254198003148301 -0.0042899348435868 0.0597355945693789"
        rpy="0 0 0" />
      <mass
        value="0.226156386299716" />
      <inertia
        ixx="0.000298264432447616"
        ixy="-8.6285503781533E-08"
        ixz="-2.54208064471585E-05"
        iyy="0.000445729865029852"
        iyz="3.08030083027245E-06"
        izz="0.000263681814976853" />
    </inertial>
    <visual>
      <origin
        xyz="0 0 0"
        rpy="0 0 0" />
      <geometry>
        <mesh
          filename="/meshes/neck_link.obj" />
      </geometry>
      <material
        name="">
        <color
          rgba="0.964705882352941 0.964705882352941 0.952941176470588 1" />
      </material>
    </visual>
    <collision>
      <origin
        xyz="0 0 0"
        rpy="0 0 0" />
      <geometry>
        <mesh
          filename="/meshes/neck_link.obj" />
      </geometry>
    </collision>
  </link>
  <joint
    name="head_roll"
    type="revolute">
    <origin
      xyz="0 0.46811 0"
      rpy="1.5708 -1.5708 0" />
    <parent
      link="chest_link" />
    <child
      link="neck_link" />
    <axis
      xyz="0 0 -1" />
    <limit
      lower="-1"
      upper="1"
      effort="0"
      velocity="2" />
  </joint>
  <link
    name="int_neck_link">
    <inertial>
      <origin
        xyz="0.00446725260220915 -0.0183808549428746 0.0300851016361073"
        rpy="0 0 0" />
      <mass
        value="0.114056596786427" />
      <inertia
        ixx="0.00012606821774216"
        ixy="2.28265988902673E-05"
        ixz="-7.8541837751612E-10"
        iyy="7.66886412489432E-05"
        iyz="8.94077252626148E-07"
        izz="0.000161197943235499" />
    </inertial>
    <visual>
      <origin
        xyz="0 0 0"
        rpy="0 0 0" />
      <geometry>
        <mesh
          filename="/meshes/int_neck_link.obj" />
      </geometry>
      <material
        name="">
        <color
          rgba="0.627450980392157 0.627450980392157 0.627450980392157 1" />
      </material>
    </visual>
    <collision>
      <origin
        xyz="0 0 0"
        rpy="0 0 0" />
      <geometry>
        <mesh
          filename="/meshes/int_neck_link.obj" />
      </geometry>
    </collision>
  </link>
  <joint
    name="head_pitch"
    type="revolute">
    <origin
      xyz="0 0.03 -0.092793"
      rpy="1.5708 -1.5708 0" />
    <parent
      link="neck_link" />
    <child
      link="int_neck_link" />
    <axis
      xyz="0 0 -1" />
    <limit
      lower="-1"
      upper="1"
      effort="0"
      velocity="2" />
  </joint>
  <link
    name="head_link">
    <inertial>
      <origin
        xyz="-0.00034972360416687 0.100321708327407 0.0462704493794094"
        rpy="0 0 0" />
      <mass
        value="0.984338424422936" />
      <inertia
        ixx="0.00909196152115448"
        ixy="1.96099549660613E-05"
        ixz="-7.54355391932556E-05"
        iyy="0.00887552436672255"
        iyz="0.00107906657883322"
        izz="0.0058997338915657" />
    </inertial>
    <visual>
      <origin
        xyz="0 0 0"
        rpy="0 0 0" />
      <geometry>
        <mesh
          filename="/meshes/head_link.obj" />
      </geometry>
      <material
        name="">
        <color
          rgba="0.964705882352941 0.964705882352941 0.952941176470588 1" />
      </material>
    </visual>
    <collision>
      <origin
        xyz="0 0 0"
        rpy="0 0 0" />
      <geometry>
        <mesh
          filename="/meshes/head_link.obj" />
      </geometry>
    </collision>
  </link>
  <joint
    name="head_yaw"
    type="revolute">
    <origin
      xyz="0 0.0583 0.03"
      rpy="1.5708 -1.5708 0" />
    <parent
      link="int_neck_link" />
    <child
      link="head_link" />
    <axis
      xyz="0 0 -1" />
    <limit
      lower="-1"
      upper="1"
      effort="0"
      velocity="2" />
  </joint>
</robot>
