<?xml version="1.0" encoding="utf-8"?>
<!-- This URDF was automatically created by SolidWorks to URDF Exporter! Originally created by Stephen Brawner (brawner@gmail.com)
     Commit Version: 1.5.1-0-g916b5db  Build Version: 1.5.7152.31018
     For more information, please see http://wiki.ros.org/sw_urdf_exporter -->
<robot xmlns:xacro="http://ros.org/wiki/xacro" name="avatar_r0_5">

  <xacro:include filename="$(find avatar_base)/urdf/wheel.xacro"/>
  <xacro:include filename="$(find luke_description)/urdf/left.urdf.xacro"/>
  <xacro:include filename="$(find luke_description)/urdf/right.urdf.xacro"/>

  <link
    name="base_link">
  </link>
  <link
    name="robot_base_link">
    <inertial>
      <origin
        xyz="-0.00059717 0.23425 0.23101"
        rpy="0 0 0" />
      <mass
        value="618.166" />
      <inertia
        ixx="0.27355"
        ixy="-3.5553E-08"
        ixz="1.7118E-08"
        iyy="0.032156"
        iyz="0.026709"
        izz="0.25168" />
    </inertial>
    <visual>
      <origin
        xyz="0 0 0"
        rpy="0 0 0" />
      <geometry>
        <mesh
          filename="package://avatar_r0_5/meshes/base_link.STL" />
      </geometry>
      <material
        name="">
        <color
          rgba="0.078431 0.078431 0.078431 1" />
      </material>
    </visual>
    <collision>
      <origin
        xyz="0 0 0"
        rpy="0 0 0" />
      <geometry>
        <mesh
          filename="package://avatar_r0_5/meshes/base_link.STL" />
      </geometry>
    </collision>
  </link>
  <joint
    name="base2base"
    type="fixed">
    <origin
      xyz="0.47189 0 0"
      rpy="0 0 1.5708" />
    <parent
      link="base_link" />
    <child
      link="robot_base_link" />
    <axis
      xyz="0 0 0" />
  </joint>
  <link
    name="platform_link">
    <inertial>
      <origin
        xyz="-0.0019169 -0.019253 0.12225"
        rpy="0 0 0" />
      <mass
        value="5.2089" />
      <inertia
        ixx="0.097524"
        ixy="-0.0012534"
        ixz="0.0012359"
        iyy="0.12991"
        iyz="0.009425"
        izz="0.12902" />
    </inertial>
    <visual>
      <origin
        xyz="0 0 0"
        rpy="0 0 0" />
      <geometry>
        <mesh
          filename="package://avatar_r0_5/meshes/platform_link.STL" />
      </geometry>
      <material
        name="">
        <color
          rgba="0.96078 0.96078 0.96471 1" />
      </material>
    </visual>
    <collision>
      <origin
        xyz="0 0 0"
        rpy="0 0 0" />
      <geometry>
        <mesh
          filename="package://avatar_r0_5/meshes/platform_link.STL" />
      </geometry>
    </collision>
  </link>
  <joint
    name="base2platform"
    type="fixed">
    <origin
      xyz="-0.00064398 0.26937 0.44804"
      rpy="0 0 0" />
    <parent
      link="robot_base_link" />
    <child
      link="platform_link" />
    <axis
      xyz="0 0 0" />
  </joint>
  <link
    name="waist_link">
    <inertial>
      <origin
        xyz="0.0018725 -0.0033609 0.1446"
        rpy="0 0 0" />
      <mass
        value="21.191" />
      <inertia
        ixx="0.19935"
        ixy="-1.3224E-06"
        ixz="0.00099714"
        iyy="0.2049"
        iyz="-0.00020488"
        izz="0.21829" />
    </inertial>
    <visual>
      <origin
        xyz="0 0 0"
        rpy="0 0 0" />
      <geometry>
        <mesh
          filename="package://avatar_r0_5/meshes/waist_link.STL" />
      </geometry>
      <material
        name="">
        <color
          rgba="0.79216 0.81961 0.93333 1" />
      </material>
    </visual>
    <collision>
      <origin
        xyz="0 0 0"
        rpy="0 0 0" />
      <geometry>
        <mesh
          filename="package://avatar_r0_5/meshes/waist_link.STL" />
      </geometry>
    </collision>
  </link>
  <joint
    name="waist_rot"
    type="fixed">
    <origin
      xyz="0 -0.24 -1.325E-05"
      rpy="0 0 -1.5708" />
    <parent
      link="platform_link" />
    <child
      link="waist_link" />
    <axis
      xyz="0 0 -1" />
    <limit
      lower="-1"
      upper="1"
      effort="0"
      velocity="2" />
  </joint>
  <link
    name="chest_link">
    <inertial>
      <origin
        xyz="0.0372440537545067 0.11132546173049 0.0211577100485159"
        rpy="0 0 0" />
      <mass
        value="0.304842527068954" />
      <inertia
        ixx="0.000294481419363187"
        ixy="0.000242567817341944"
        ixz="-5.52363714472291E-07"
        iyy="0.00103928704482828"
        iyz="4.86582984793202E-06"
        izz="0.00120731891145862" />
    </inertial>
    <visual>
      <origin
        xyz="0 0 0"
        rpy="0 0 0" />
      <geometry>
        <mesh
          filename="package://avatar_r0_5/meshes/chest_link.STL" />
      </geometry>
      <material
        name="">
        <color
          rgba="0.956862745098039 0.96078431372549 0.964705882352941 1" />
      </material>
    </visual>
    <collision>
      <origin
        xyz="0 0 0"
        rpy="0 0 0" />
      <geometry>
        <mesh
          filename="package://avatar_r0_5/meshes/chest_link.STL" />
      </geometry>
    </collision>
  </link>
  <joint
    name="waist_tilt"
    type="fixed">
    <origin
      xyz="0.026019 0 0.336"
      rpy="1.5708 0 1.5708" />
    <parent
      link="waist_link" />
    <child
      link="chest_link" />
    <axis
      xyz="-1 0 0" />
    <limit
      lower="0"
      upper="1"
      effort="0"
      velocity="2" />
  </joint>
  <link
    name="headset_static_link"/>
  <joint
    name="headset_static"
    type="fixed">
    <origin
      xyz="0 0.561 -0.058" />
    <parent
      link="chest_link" />
    <child
      link="headset_static_link" />
    <axis
      xyz="0 0 0" />
  </joint>
  <link
    name="r_should_axis_link">
    <inertial>
      <origin
        xyz="0.0271747977618289 -2.87714544225082E-05 0.0136872715581331"
        rpy="0 0 0" />
      <mass
        value="0.0760510742436307" />
      <inertia
        ixx="5.01097287434105E-05"
        ixy="3.09946970417366E-08"
        ixz="2.474321199555E-05"
        iyy="0.000103376219183421"
        iyz="1.77481964668466E-08"
        izz="0.000115998977330436" />
    </inertial>
    <visual>
      <origin
        xyz="0 0 0"
        rpy="0 0 0" />
      <geometry>
        <mesh
          filename="package://avatar_r0_5/meshes/r_should_axis_link.STL" />
      </geometry>
      <material
        name="">
        <color
          rgba="0.96078431372549 0.96078431372549 0.964705882352941 1" />
      </material>
    </visual>
    <collision>
      <origin
        xyz="0 0 0"
        rpy="0 0 0" />
      <geometry>
        <mesh
          filename="package://avatar_r0_5/meshes/r_should_axis_link.STL" />
      </geometry>
    </collision>
  </link>
  <joint
    name="right_shoulder_add"
    type="revolute">
    <origin
      xyz="-0.10061 0.416 0"
      rpy="1.5708 0 3.1416" />
    <parent
      link="chest_link" />
    <child
      link="r_should_axis_link" />
    <axis
      xyz="0 0 -1" />
    <limit
      lower="-0.4"
      upper="0.75"
      effort="1"
      velocity="1.0" />
  </joint>
  <link
    name="r_interface_link">
    <inertial>
        <mass value="2e-06"/>
        <inertia ixx="1.1e-09" ixy="0" ixz="0" iyy="1.1e-09" iyz="0" izz="1.1e-09"/>
    </inertial>
  </link>
  <joint
    name="r_rot2int"
    type="fixed">
    <origin
      xyz="0.065 0 0"
      rpy="1.5708 0 -1.5708" />
    <parent
      link="r_should_axis_link" />
    <child
      link="r_interface_link" />
    <axis
      xyz="0 0 0" />
  </joint>
  <link
    name="l_should_axis_link">
    <inertial>
      <origin
        xyz="0.0271746660088268 -7.81820416141978E-05 0.0136872746188932"
        rpy="0 0 0" />
      <mass
        value="0.0760509825087617" />
      <inertia
        ixx="5.01100039793683E-05"
        ixy="1.27864503626856E-07"
        ixz="2.47431993244341E-05"
        iyy="0.000103375868748006"
        iyz="-2.72311343991148E-08"
        izz="0.000115998907803854" />
    </inertial>
    <visual>
      <origin
        xyz="0 0 0"
        rpy="0 0 0" />
      <geometry>
        <mesh
          filename="package://avatar_r0_5/meshes/l_should_axis_link.STL" />
      </geometry>
      <material
        name="">
        <color
          rgba="0.96078431372549 0.96078431372549 0.964705882352941 1" />
      </material>
    </visual>
    <collision>
      <origin
        xyz="0 0 0"
        rpy="0 0 0" />
      <geometry>
        <mesh
          filename="package://avatar_r0_5/meshes/l_should_axis_link.STL" />
      </geometry>
    </collision>
  </link>
  <joint
    name="left_shoulder_add"
    type="revolute">
    <origin
      xyz="0.10061 0.416 0"
      rpy="-1.5708 0 0" />
    <parent
      link="chest_link" />
    <child
      link="l_should_axis_link" />
    <axis
      xyz="0 0 -1" />
    <limit
      lower="-0.4"
      upper="0.75"
      effort="1"
      velocity="1.0" />
  </joint>
  <link
    name="l_interface_link">
    <inertial>
        <mass value="2e-06"/>
        <inertia ixx="1.1e-09" ixy="0" ixz="0" iyy="1.1e-09" iyz="0" izz="1.1e-09"/>
    </inertial>
  </link>
  <joint
    name="l_rot2int"
    type="fixed">
    <origin
      xyz="0.065 0 0"
      rpy="1.5708 0 -1.5708" />
    <parent
      link="l_should_axis_link" />
    <child
      link="l_interface_link" />
    <axis
      xyz="0 0 0" />
  </joint>
  <link
    name="neck_link">
    <inertial>
      <origin
        xyz="0.00254198003148301 -0.0042899348435868 0.0597355945693789"
        rpy="0 0 0" />
      <mass
        value="0.226156386299716" />
      <inertia
        ixx="0.000298264432447616"
        ixy="-8.6285503781533E-08"
        ixz="-2.54208064471585E-05"
        iyy="0.000445729865029852"
        iyz="3.08030083027245E-06"
        izz="0.000263681814976853" />
    </inertial>
    <visual>
      <origin
        xyz="0 0 0"
        rpy="0 0 0" />
      <geometry>
        <mesh
          filename="package://avatar_r0_5/meshes/neck_link.STL" />
      </geometry>
      <material
        name="">
        <color
          rgba="0.964705882352941 0.964705882352941 0.952941176470588 1" />
      </material>
    </visual>
    <collision>
      <origin
        xyz="0 0 0"
        rpy="0 0 0" />
      <geometry>
        <mesh
          filename="package://avatar_r0_5/meshes/neck_link.STL" />
      </geometry>
    </collision>
  </link>
  <joint
    name="head_roll"
    type="revolute">
    <origin
      xyz="0 0.46811 0"
      rpy="1.5708 -1.5708 0" />
    <parent
      link="chest_link" />
    <child
      link="neck_link" />
    <axis
      xyz="0 0 -1" />
    <limit
      lower="-1"
      upper="1"
      effort="0"
      velocity="2" />
  </joint>
  <link
    name="int_neck_link">
    <inertial>
      <origin
        xyz="0.00446725260220915 -0.0183808549428746 0.0300851016361073"
        rpy="0 0 0" />
      <mass
        value="0.114056596786427" />
      <inertia
        ixx="0.00012606821774216"
        ixy="2.28265988902673E-05"
        ixz="-7.8541837751612E-10"
        iyy="7.66886412489432E-05"
        iyz="8.94077252626148E-07"
        izz="0.000161197943235499" />
    </inertial>
    <visual>
      <origin
        xyz="0 0 0"
        rpy="0 0 0" />
      <geometry>
        <mesh
          filename="package://avatar_r0_5/meshes/int_neck_link.STL" />
      </geometry>
      <material
        name="">
        <color
          rgba="0.627450980392157 0.627450980392157 0.627450980392157 1" />
      </material>
    </visual>
    <collision>
      <origin
        xyz="0 0 0"
        rpy="0 0 0" />
      <geometry>
        <mesh
          filename="package://avatar_r0_5/meshes/int_neck_link.STL" />
      </geometry>
    </collision>
  </link>
  <joint
    name="head_pitch"
    type="revolute">
    <origin
      xyz="0 0.03 -0.092793"
      rpy="1.5708 -1.5708 0" />
    <parent
      link="neck_link" />
    <child
      link="int_neck_link" />
    <axis
      xyz="0 0 -1" />
    <limit
      lower="-1"
      upper="1"
      effort="0"
      velocity="2" />
  </joint>
  <link
    name="head_link">
    <inertial>
      <origin
        xyz="-0.00034972360416687 0.100321708327407 0.0462704493794094"
        rpy="0 0 0" />
      <mass
        value="0.984338424422936" />
      <inertia
        ixx="0.00909196152115448"
        ixy="1.96099549660613E-05"
        ixz="-7.54355391932556E-05"
        iyy="0.00887552436672255"
        iyz="0.00107906657883322"
        izz="0.0058997338915657" />
    </inertial>
    <visual>
      <origin
        xyz="0 0 0"
        rpy="0 0 0" />
      <geometry>
        <mesh
          filename="package://avatar_r0_5/meshes/head_link.STL" />
      </geometry>
      <material
        name="">
        <color
          rgba="0.964705882352941 0.964705882352941 0.952941176470588 1" />
      </material>
    </visual>
    <collision>
      <origin
        xyz="0 0 0"
        rpy="0 0 0" />
      <geometry>
        <mesh
          filename="package://avatar_r0_5/meshes/head_link.STL" />
      </geometry>
    </collision>
  </link>
  <joint
    name="head_yaw"
    type="revolute">
    <origin
      xyz="0 0.0583 0.03"
      rpy="1.5708 -1.5708 0" />
    <parent
      link="int_neck_link" />
    <child
      link="head_link" />
    <axis
      xyz="0 0 -1" />
    <limit
      lower="-1"
      upper="1"
      effort="0"
      velocity="2" />
  </joint>


  <gazebo reference="head_link">
    <sensor type="multicamera" name="stereo_camera">
      <update_rate>30.0</update_rate>
      <camera name="left">
        <pose>0.34 0.08 0.18 -1.5 -1.57079632679 0</pose>
        <horizontal_fov>1.5</horizontal_fov>
        <image>
          <width>2000</width>
          <height>2000</height>
          <format>R8G8B8</format>
        </image>
        <clip>
          <near>0.02</near>
          <far>300</far>
        </clip>
        <noise>
          <type>gaussian</type>
          <mean>0.0</mean>
          <stddev>0.007</stddev>
        </noise>
      </camera>
      <camera name="right">
        <pose>-0.34 0.08 0.18 -1.5 -1.57079632679 0</pose>
        <horizontal_fov>1.5</horizontal_fov>
        <image>
          <width>2000</width>
          <height>2000</height>
          <format>R8G8B8</format>
        </image>
        <clip>
          <near>0.02</near>
          <far>300</far>
        </clip>
        <noise>
          <type>gaussian</type>
          <mean>0.0</mean>
          <stddev>0.007</stddev>
        </noise>
      </camera>
      <plugin name="stereo_camera_controller" filename="libgazebo_ros_multicamera.so">
        <alwaysOn>true</alwaysOn>
        <updateRate>30.0</updateRate>
        <cameraName>stereo</cameraName>
        <imageTopicName>image_raw</imageTopicName>
        <cameraInfoTopicName>camera_info</cameraInfoTopicName>
        <frameName>headset_ref_link</frameName>
        <!--<rightFrameName>right_camera_optical_frame</rightFrameName>-->
        <hackBaseline>0.07</hackBaseline>
        <distortionK1>0.0</distortionK1>
        <distortionK2>0.0</distortionK2>
        <distortionK3>0.0</distortionK3>
        <distortionT1>0.0</distortionT1>
        <distortionT2>0.0</distortionT2>
      </plugin>
    </sensor>
  </gazebo>


  <xacro:wheel wheel_prefix="back_right" fixed='false' zaxis_dir='1.0'>
    <origin xyz="-0.288475010713314 0.47189 0.15651" rpy="0 1.5707963267949 0"/>
  </xacro:wheel>
  <xacro:wheel wheel_prefix="back_left" fixed='false' zaxis_dir='-1.0'>
    <origin xyz="0.288475010713314 0.47189 0.15651" rpy="0 -1.5707963267949 0"/>
  </xacro:wheel>

  <!-- Make Arms -->
  <xacro:luke_right_arm parent_link="r_interface_link" shoulder_width="0.035">
    <origin xyz="0 0 -0.035" rpy="0.02569452348 3.1415926 0"/>
  </xacro:luke_right_arm>

  <xacro:luke_left_arm parent_link="l_interface_link" shoulder_width="0.035">
    <origin xyz="0 0 -0.035" rpy="0.02569452348 0 0"/>
  </xacro:luke_left_arm>

  <link
    name="left_end">
    <inertial>
      <origin xyz="0 0 1" rpy="0 0 0"/>
      <mass value="1e-1"/>
      <inertia
        ixx="1e-2" ixy="0.0" ixz="0.0"
        iyy="1e-2" iyz="0.0"
        izz="1e-2"/>
    </inertial>
  </link>



  <!-- <gazebo reference="left_end"/> -->
  <!-->
  <joint
    name="left_static"
    type="fixed">
    <origin
      xyz="0 0 0"
      rpy="0 0 0" />
    <parent
      link="headset_static_link" />
    <child
      link="left_end" />
    <axis
      xyz="0 0 0" />
  </joint>
  </!-->

  <joint
    name="left_static"
    type="fixed">

    <!-- Vive controller -->
    <origin
      xyz="-0.00077349 0.0012316 0.075483"
      rpy="1.57079632679 3.1415926 -0.4961623" />

    <!-- unsure/original -->
    <!-->
    <origin
      xyz="0 0 0.05"
      rpy="-3.1514926 0 0" />
    </!-->

    <!-- index controller -->
    <!-->
    <origin
      xyz="-0.00077349 0.0012316 0.075483"
      rpy="-0.767 0.0 0.4961623" />
    </!-->
    <parent
      link="left_Palm-1" />
    <child
      link="left_end" />
    <axis
      xyz="0 0 0" />
  </joint>

  <link
    name="right_end">
    <inertial>
      <origin xyz="0 0 1" rpy="0 0 0"/>
      <mass value="1e-1"/>
      <inertia
        ixx="1e-2" ixy="0.0" ixz="0.0"
        iyy="1e-2" iyz="0.0"
        izz="1e-2"/>
    </inertial>
  </link>

  <!-- <gazebo reference="right_end"/> -->

  <joint
    name="right_static"
    type="fixed">

    <!-- Vive controller -->
    <origin
      xyz="-0.00077349 0.0012316 0.075483"
      rpy="-1.57079632679 0.0 0.4961623" />

    <!-- unsure/original -->
    <!-->
    <origin
      xyz="0 0 0.05"
      rpy="-3.1514926 0 0" />
    </!-->

    <!-- index controller -->
    <!-->
    <origin
      xyz="-0.00077349 0.0012316 0.075483"
      rpy="-0.767 0.0 0.4961623" />
    </!-->
    <parent
      link="right_Palm-1" />
    <child
      link="right_end" />
    <axis
      xyz="0 0 0" />
  </joint>

  <link
  name="right_elbow">
  <inertial>
    <origin xyz="0 0 1" rpy="0 0 0"/>
    <mass value="1e-1"/>
    <inertia
      ixx="1e-2" ixy="0.0" ixz="0.0"
      iyy="1e-2" iyz="0.0"
      izz="1e-2"/>
  </inertial>
  </link>


  <joint
    name="right_elbow_static"
    type="fixed">

    <!-- Vive controller -->
    <origin
      xyz="0 0 0"
      rpy="0 -3.1415926 0.0" />
    <parent
      link="right_HR" />
    <child
      link="right_elbow" />
    <axis
      xyz="0 0 0" />
  </joint>

  <link
  name="left_elbow">
  <inertial>
    <origin xyz="0 0 1" rpy="0 0 0"/>
    <mass value="1e-1"/>
    <inertia
      ixx="1e-2" ixy="0.0" ixz="0.0"
      iyy="1e-2" iyz="0.0"
      izz="1e-2"/>
  </inertial>
  </link>


  <joint
  name="left_elbow_static"
  type="fixed">

  <!-- Vive controller -->
  <origin
    xyz="0 0 0"
    rpy="0 0.0 0" />
  <parent
    link="left_HR" />
  <child
    link="left_elbow" />
  <axis
    xyz="0 0 0" />
  </joint>

   <gazebo>
    <plugin name="gazebo_ros_control" filename="libgazebo_ros_control.so">
      <robotNamespace>/</robotNamespace>
    </plugin>
  </gazebo>
 <transmission name="head_pitch_trans">
    <type>transmission_interface/SimpleTransmission</type>
    <actuator name="$head_pitch_motor">
      <mechanicalReduction>1</mechanicalReduction>
    </actuator>
    <joint name="head_pitch">
      <hardwareInterface>hardware_interface/PositionJointInterface</hardwareInterface>
    </joint>
  </transmission>
 <transmission name="head_roll_trans">
    <type>transmission_interface/SimpleTransmission</type>
    <actuator name="$head_roll_motor">
      <mechanicalReduction>1</mechanicalReduction>
    </actuator>
    <joint name="head_roll">
      <hardwareInterface>hardware_interface/PositionJointInterface</hardwareInterface>
    </joint>
  </transmission>
   <transmission name="head_yaw_trans">
    <type>transmission_interface/SimpleTransmission</type>
    <actuator name="$head_yaw_motor">
      <mechanicalReduction>1</mechanicalReduction>
    </actuator>
    <joint name="head_yaw">
      <hardwareInterface>hardware_interface/PositionJointInterface</hardwareInterface>
    </joint>
  </transmission>
   <transmission name="left_shoulder_add_trans">
    <type>transmission_interface/SimpleTransmission</type>
    <actuator name="$left_shoulder_add_motor">
      <mechanicalReduction>1</mechanicalReduction>
    </actuator>
    <joint name="left_shoulder_add">
      <hardwareInterface>hardware_interface/PositionJointInterface</hardwareInterface>
    </joint>
  </transmission>
   <transmission name="right_shoulder_add_trans">
    <type>transmission_interface/SimpleTransmission</type>
    <actuator name="$right_shoulder_add_motor">
      <mechanicalReduction>1</mechanicalReduction>
    </actuator>
    <joint name="right_shoulder_add">
      <hardwareInterface>hardware_interface/PositionJointInterface</hardwareInterface>
    </joint>
  </transmission>
</robot>
